{
 "cells": [
  {
   "cell_type": "code",
   "execution_count": null,
   "id": "448baa3a",
   "metadata": {},
   "outputs": [
    {
     "name": "stderr",
     "output_type": "stream",
     "text": [
      "ERROR:root:Internal Python error in the inspect module.\n",
      "Below is the traceback from this internal error.\n",
      "\n",
      "ERROR:root:Internal Python error in the inspect module.\n",
      "Below is the traceback from this internal error.\n",
      "\n",
      "ERROR:root:Internal Python error in the inspect module.\n",
      "Below is the traceback from this internal error.\n",
      "\n"
     ]
    },
    {
     "name": "stdout",
     "output_type": "stream",
     "text": [
      "Traceback (most recent call last):\n",
      "  File \"/opt/anaconda3/lib/python3.8/site-packages/IPython/core/interactiveshell.py\", line 3437, in run_code\n",
      "    exec(code_obj, self.user_global_ns, self.user_ns)\n",
      "  File \"<ipython-input-1-c7acc240809e>\", line 3, in <module>\n",
      "    import pandas as pd\n",
      "  File \"<frozen importlib._bootstrap>\", line 991, in _find_and_load\n",
      "  File \"<frozen importlib._bootstrap>\", line 971, in _find_and_load_unlocked\n",
      "  File \"<frozen importlib._bootstrap>\", line 914, in _find_spec\n",
      "  File \"<frozen importlib._bootstrap_external>\", line 1342, in find_spec\n",
      "  File \"<frozen importlib._bootstrap_external>\", line 1311, in _get_spec\n",
      "  File \"<frozen importlib._bootstrap_external>\", line 1275, in _path_importer_cache\n",
      "PermissionError: [Errno 1] Operation not permitted\n",
      "\n",
      "During handling of the above exception, another exception occurred:\n",
      "\n",
      "Traceback (most recent call last):\n",
      "  File \"/opt/anaconda3/lib/python3.8/site-packages/IPython/core/interactiveshell.py\", line 2061, in showtraceback\n",
      "    stb = value._render_traceback_()\n",
      "AttributeError: 'PermissionError' object has no attribute '_render_traceback_'\n",
      "\n",
      "During handling of the above exception, another exception occurred:\n",
      "\n",
      "Traceback (most recent call last):\n",
      "  File \"/opt/anaconda3/lib/python3.8/site-packages/IPython/core/ultratb.py\", line 1101, in get_records\n",
      "    return _fixed_getinnerframes(etb, number_of_lines_of_context, tb_offset)\n",
      "  File \"/opt/anaconda3/lib/python3.8/site-packages/IPython/core/ultratb.py\", line 248, in wrapped\n",
      "    return f(*args, **kwargs)\n",
      "  File \"/opt/anaconda3/lib/python3.8/site-packages/IPython/core/ultratb.py\", line 281, in _fixed_getinnerframes\n",
      "    records = fix_frame_records_filenames(inspect.getinnerframes(etb, context))\n",
      "  File \"/opt/anaconda3/lib/python3.8/inspect.py\", line 1515, in getinnerframes\n",
      "    frameinfo = (tb.tb_frame,) + getframeinfo(tb, context)\n",
      "  File \"/opt/anaconda3/lib/python3.8/inspect.py\", line 1473, in getframeinfo\n",
      "    filename = getsourcefile(frame) or getfile(frame)\n",
      "  File \"/opt/anaconda3/lib/python3.8/inspect.py\", line 708, in getsourcefile\n",
      "    if getattr(getmodule(object, filename), '__loader__', None) is not None:\n",
      "  File \"/opt/anaconda3/lib/python3.8/inspect.py\", line 737, in getmodule\n",
      "    file = getabsfile(object, _filename)\n",
      "  File \"/opt/anaconda3/lib/python3.8/inspect.py\", line 721, in getabsfile\n",
      "    return os.path.normcase(os.path.abspath(_filename))\n",
      "  File \"/opt/anaconda3/lib/python3.8/posixpath.py\", line 379, in abspath\n",
      "    cwd = os.getcwd()\n",
      "PermissionError: [Errno 1] Operation not permitted\n",
      "Traceback (most recent call last):\n",
      "  File \"/opt/anaconda3/lib/python3.8/site-packages/IPython/core/interactiveshell.py\", line 3437, in run_code\n",
      "    exec(code_obj, self.user_global_ns, self.user_ns)\n",
      "  File \"<ipython-input-1-c7acc240809e>\", line 3, in <module>\n",
      "    import pandas as pd\n",
      "  File \"<frozen importlib._bootstrap>\", line 991, in _find_and_load\n",
      "  File \"<frozen importlib._bootstrap>\", line 971, in _find_and_load_unlocked\n",
      "  File \"<frozen importlib._bootstrap>\", line 914, in _find_spec\n",
      "  File \"<frozen importlib._bootstrap_external>\", line 1342, in find_spec\n",
      "  File \"<frozen importlib._bootstrap_external>\", line 1311, in _get_spec\n",
      "  File \"<frozen importlib._bootstrap_external>\", line 1275, in _path_importer_cache\n",
      "PermissionError: [Errno 1] Operation not permitted\n",
      "\n",
      "During handling of the above exception, another exception occurred:\n",
      "\n",
      "Traceback (most recent call last):\n",
      "  File \"/opt/anaconda3/lib/python3.8/site-packages/IPython/core/interactiveshell.py\", line 2061, in showtraceback\n",
      "    stb = value._render_traceback_()\n",
      "AttributeError: 'PermissionError' object has no attribute '_render_traceback_'\n",
      "\n",
      "During handling of the above exception, another exception occurred:\n",
      "\n",
      "Traceback (most recent call last):\n",
      "  File \"/opt/anaconda3/lib/python3.8/site-packages/IPython/core/interactiveshell.py\", line 3357, in run_ast_nodes\n",
      "    if (await self.run_code(code, result,  async_=asy)):\n",
      "  File \"/opt/anaconda3/lib/python3.8/site-packages/IPython/core/interactiveshell.py\", line 3454, in run_code\n",
      "    self.showtraceback(running_compiled_code=True)\n",
      "  File \"/opt/anaconda3/lib/python3.8/site-packages/IPython/core/interactiveshell.py\", line 2063, in showtraceback\n",
      "    stb = self.InteractiveTB.structured_traceback(etype,\n",
      "  File \"/opt/anaconda3/lib/python3.8/site-packages/IPython/core/ultratb.py\", line 1367, in structured_traceback\n",
      "    return FormattedTB.structured_traceback(\n",
      "  File \"/opt/anaconda3/lib/python3.8/site-packages/IPython/core/ultratb.py\", line 1267, in structured_traceback\n",
      "    return VerboseTB.structured_traceback(\n",
      "  File \"/opt/anaconda3/lib/python3.8/site-packages/IPython/core/ultratb.py\", line 1124, in structured_traceback\n",
      "    formatted_exception = self.format_exception_as_a_whole(etype, evalue, etb, number_of_lines_of_context,\n",
      "  File \"/opt/anaconda3/lib/python3.8/site-packages/IPython/core/ultratb.py\", line 1082, in format_exception_as_a_whole\n",
      "    last_unique, recursion_repeat = find_recursion(orig_etype, evalue, records)\n",
      "  File \"/opt/anaconda3/lib/python3.8/site-packages/IPython/core/ultratb.py\", line 382, in find_recursion\n",
      "    return len(records), 0\n",
      "TypeError: object of type 'NoneType' has no len()\n",
      "\n",
      "During handling of the above exception, another exception occurred:\n",
      "\n",
      "Traceback (most recent call last):\n",
      "  File \"/opt/anaconda3/lib/python3.8/site-packages/IPython/core/interactiveshell.py\", line 2061, in showtraceback\n",
      "    stb = value._render_traceback_()\n",
      "AttributeError: 'TypeError' object has no attribute '_render_traceback_'\n",
      "\n",
      "During handling of the above exception, another exception occurred:\n",
      "\n",
      "Traceback (most recent call last):\n",
      "  File \"/opt/anaconda3/lib/python3.8/site-packages/IPython/core/ultratb.py\", line 1101, in get_records\n",
      "    return _fixed_getinnerframes(etb, number_of_lines_of_context, tb_offset)\n",
      "  File \"/opt/anaconda3/lib/python3.8/site-packages/IPython/core/ultratb.py\", line 248, in wrapped\n",
      "    return f(*args, **kwargs)\n",
      "  File \"/opt/anaconda3/lib/python3.8/site-packages/IPython/core/ultratb.py\", line 281, in _fixed_getinnerframes\n",
      "    records = fix_frame_records_filenames(inspect.getinnerframes(etb, context))\n",
      "  File \"/opt/anaconda3/lib/python3.8/inspect.py\", line 1515, in getinnerframes\n",
      "    frameinfo = (tb.tb_frame,) + getframeinfo(tb, context)\n",
      "  File \"/opt/anaconda3/lib/python3.8/inspect.py\", line 1473, in getframeinfo\n",
      "    filename = getsourcefile(frame) or getfile(frame)\n",
      "  File \"/opt/anaconda3/lib/python3.8/inspect.py\", line 708, in getsourcefile\n",
      "    if getattr(getmodule(object, filename), '__loader__', None) is not None:\n",
      "  File \"/opt/anaconda3/lib/python3.8/inspect.py\", line 737, in getmodule\n",
      "    file = getabsfile(object, _filename)\n",
      "  File \"/opt/anaconda3/lib/python3.8/inspect.py\", line 721, in getabsfile\n",
      "    return os.path.normcase(os.path.abspath(_filename))\n",
      "  File \"/opt/anaconda3/lib/python3.8/posixpath.py\", line 379, in abspath\n",
      "    cwd = os.getcwd()\n",
      "PermissionError: [Errno 1] Operation not permitted\n",
      "Traceback (most recent call last):\n",
      "  File \"/opt/anaconda3/lib/python3.8/site-packages/IPython/core/interactiveshell.py\", line 3437, in run_code\n",
      "    exec(code_obj, self.user_global_ns, self.user_ns)\n",
      "  File \"<ipython-input-1-c7acc240809e>\", line 3, in <module>\n",
      "    import pandas as pd\n",
      "  File \"<frozen importlib._bootstrap>\", line 991, in _find_and_load\n",
      "  File \"<frozen importlib._bootstrap>\", line 971, in _find_and_load_unlocked\n",
      "  File \"<frozen importlib._bootstrap>\", line 914, in _find_spec\n",
      "  File \"<frozen importlib._bootstrap_external>\", line 1342, in find_spec\n",
      "  File \"<frozen importlib._bootstrap_external>\", line 1311, in _get_spec\n",
      "  File \"<frozen importlib._bootstrap_external>\", line 1275, in _path_importer_cache\n",
      "PermissionError: [Errno 1] Operation not permitted\n",
      "\n",
      "During handling of the above exception, another exception occurred:\n",
      "\n",
      "Traceback (most recent call last):\n",
      "  File \"/opt/anaconda3/lib/python3.8/site-packages/IPython/core/interactiveshell.py\", line 2061, in showtraceback\n",
      "    stb = value._render_traceback_()\n",
      "AttributeError: 'PermissionError' object has no attribute '_render_traceback_'\n",
      "\n",
      "During handling of the above exception, another exception occurred:\n",
      "\n",
      "Traceback (most recent call last):\n",
      "  File \"/opt/anaconda3/lib/python3.8/site-packages/IPython/core/interactiveshell.py\", line 3357, in run_ast_nodes\n",
      "    if (await self.run_code(code, result,  async_=asy)):\n",
      "  File \"/opt/anaconda3/lib/python3.8/site-packages/IPython/core/interactiveshell.py\", line 3454, in run_code\n",
      "    self.showtraceback(running_compiled_code=True)\n",
      "  File \"/opt/anaconda3/lib/python3.8/site-packages/IPython/core/interactiveshell.py\", line 2063, in showtraceback\n",
      "    stb = self.InteractiveTB.structured_traceback(etype,\n",
      "  File \"/opt/anaconda3/lib/python3.8/site-packages/IPython/core/ultratb.py\", line 1367, in structured_traceback\n",
      "    return FormattedTB.structured_traceback(\n",
      "  File \"/opt/anaconda3/lib/python3.8/site-packages/IPython/core/ultratb.py\", line 1267, in structured_traceback\n",
      "    return VerboseTB.structured_traceback(\n",
      "  File \"/opt/anaconda3/lib/python3.8/site-packages/IPython/core/ultratb.py\", line 1124, in structured_traceback\n",
      "    formatted_exception = self.format_exception_as_a_whole(etype, evalue, etb, number_of_lines_of_context,\n",
      "  File \"/opt/anaconda3/lib/python3.8/site-packages/IPython/core/ultratb.py\", line 1082, in format_exception_as_a_whole\n",
      "    last_unique, recursion_repeat = find_recursion(orig_etype, evalue, records)\n",
      "  File \"/opt/anaconda3/lib/python3.8/site-packages/IPython/core/ultratb.py\", line 382, in find_recursion\n",
      "    return len(records), 0\n",
      "TypeError: object of type 'NoneType' has no len()\n",
      "\n",
      "During handling of the above exception, another exception occurred:\n",
      "\n",
      "Traceback (most recent call last):\n",
      "  File \"/opt/anaconda3/lib/python3.8/site-packages/IPython/core/interactiveshell.py\", line 2061, in showtraceback\n",
      "    stb = value._render_traceback_()\n",
      "AttributeError: 'TypeError' object has no attribute '_render_traceback_'\n",
      "\n",
      "During handling of the above exception, another exception occurred:\n",
      "\n",
      "Traceback (most recent call last):\n",
      "  File \"/opt/anaconda3/lib/python3.8/site-packages/IPython/core/interactiveshell.py\", line 2940, in _run_cell\n",
      "    return runner(coro)\n",
      "  File \"/opt/anaconda3/lib/python3.8/site-packages/IPython/core/async_helpers.py\", line 68, in _pseudo_sync_runner\n",
      "    coro.send(None)\n",
      "  File \"/opt/anaconda3/lib/python3.8/site-packages/IPython/core/interactiveshell.py\", line 3165, in run_cell_async\n",
      "    has_raised = await self.run_ast_nodes(code_ast.body, cell_name,\n",
      "  File \"/opt/anaconda3/lib/python3.8/site-packages/IPython/core/interactiveshell.py\", line 3376, in run_ast_nodes\n",
      "    self.showtraceback()\n",
      "  File \"/opt/anaconda3/lib/python3.8/site-packages/IPython/core/interactiveshell.py\", line 2063, in showtraceback\n",
      "    stb = self.InteractiveTB.structured_traceback(etype,\n",
      "  File \"/opt/anaconda3/lib/python3.8/site-packages/IPython/core/ultratb.py\", line 1367, in structured_traceback\n",
      "    return FormattedTB.structured_traceback(\n",
      "  File \"/opt/anaconda3/lib/python3.8/site-packages/IPython/core/ultratb.py\", line 1267, in structured_traceback\n",
      "    return VerboseTB.structured_traceback(\n",
      "  File \"/opt/anaconda3/lib/python3.8/site-packages/IPython/core/ultratb.py\", line 1142, in structured_traceback\n",
      "    formatted_exceptions += self.format_exception_as_a_whole(etype, evalue, etb, lines_of_context,\n",
      "  File \"/opt/anaconda3/lib/python3.8/site-packages/IPython/core/ultratb.py\", line 1082, in format_exception_as_a_whole\n",
      "    last_unique, recursion_repeat = find_recursion(orig_etype, evalue, records)\n",
      "  File \"/opt/anaconda3/lib/python3.8/site-packages/IPython/core/ultratb.py\", line 382, in find_recursion\n",
      "    return len(records), 0\n",
      "TypeError: object of type 'NoneType' has no len()\n",
      "\n",
      "During handling of the above exception, another exception occurred:\n",
      "\n",
      "Traceback (most recent call last):\n",
      "  File \"/opt/anaconda3/lib/python3.8/site-packages/IPython/core/interactiveshell.py\", line 2061, in showtraceback\n",
      "    stb = value._render_traceback_()\n",
      "AttributeError: 'TypeError' object has no attribute '_render_traceback_'\n",
      "\n",
      "During handling of the above exception, another exception occurred:\n",
      "\n",
      "Traceback (most recent call last):\n",
      "  File \"/opt/anaconda3/lib/python3.8/site-packages/IPython/core/ultratb.py\", line 1101, in get_records\n",
      "    return _fixed_getinnerframes(etb, number_of_lines_of_context, tb_offset)\n",
      "  File \"/opt/anaconda3/lib/python3.8/site-packages/IPython/core/ultratb.py\", line 248, in wrapped\n",
      "    return f(*args, **kwargs)\n",
      "  File \"/opt/anaconda3/lib/python3.8/site-packages/IPython/core/ultratb.py\", line 281, in _fixed_getinnerframes\n",
      "    records = fix_frame_records_filenames(inspect.getinnerframes(etb, context))\n",
      "  File \"/opt/anaconda3/lib/python3.8/inspect.py\", line 1515, in getinnerframes\n",
      "    frameinfo = (tb.tb_frame,) + getframeinfo(tb, context)\n",
      "  File \"/opt/anaconda3/lib/python3.8/inspect.py\", line 1473, in getframeinfo\n",
      "    filename = getsourcefile(frame) or getfile(frame)\n",
      "  File \"/opt/anaconda3/lib/python3.8/inspect.py\", line 708, in getsourcefile\n",
      "    if getattr(getmodule(object, filename), '__loader__', None) is not None:\n",
      "  File \"/opt/anaconda3/lib/python3.8/inspect.py\", line 737, in getmodule\n",
      "    file = getabsfile(object, _filename)\n",
      "  File \"/opt/anaconda3/lib/python3.8/inspect.py\", line 721, in getabsfile\n",
      "    return os.path.normcase(os.path.abspath(_filename))\n",
      "  File \"/opt/anaconda3/lib/python3.8/posixpath.py\", line 379, in abspath\n",
      "    cwd = os.getcwd()\n",
      "PermissionError: [Errno 1] Operation not permitted\n"
     ]
    }
   ],
   "source": [
    "import os\n",
    "import glob\n",
    "import pandas as pd\n",
    "# os.chdir(\"/directory\")"
   ]
  },
  {
   "cell_type": "code",
   "execution_count": 2,
   "id": "be8c2a38",
   "metadata": {},
   "outputs": [],
   "source": [
    "os.chdir(\"viral_genomes\")"
   ]
  },
  {
   "cell_type": "code",
   "execution_count": 3,
   "id": "b09ce719",
   "metadata": {},
   "outputs": [],
   "source": [
    "file_extension = '.csv'\n",
    "all_filenames = [i for i in glob.glob(f\"*{file_extension}\")]"
   ]
  },
  {
   "cell_type": "code",
   "execution_count": 4,
   "id": "007fd224",
   "metadata": {},
   "outputs": [
    {
     "data": {
      "text/plain": [
       "['Virus_classification_entire_data_4.csv',\n",
       " 'Virus_classification_entire_data_5.csv',\n",
       " 'Virus_classification_entire_data_6.csv',\n",
       " 'Virus_classification_entire_data_2.csv',\n",
       " 'Virus_classification_entire_data_3.csv',\n",
       " 'Virus_classification_entire_data_1.csv',\n",
       " 'Virus_classification_entire_data_0.csv']"
      ]
     },
     "execution_count": 4,
     "metadata": {},
     "output_type": "execute_result"
    }
   ],
   "source": [
    "all_filenames"
   ]
  },
  {
   "cell_type": "code",
   "execution_count": 5,
   "id": "9a95bad3",
   "metadata": {},
   "outputs": [
    {
     "data": {
      "text/plain": [
       "['Virus_classification_entire_data_0.csv',\n",
       " 'Virus_classification_entire_data_1.csv',\n",
       " 'Virus_classification_entire_data_2.csv',\n",
       " 'Virus_classification_entire_data_3.csv',\n",
       " 'Virus_classification_entire_data_4.csv',\n",
       " 'Virus_classification_entire_data_5.csv',\n",
       " 'Virus_classification_entire_data_6.csv']"
      ]
     },
     "execution_count": 5,
     "metadata": {},
     "output_type": "execute_result"
    }
   ],
   "source": [
    "all_filenames.sort()\n",
    "all_filenames"
   ]
  },
  {
   "cell_type": "code",
   "execution_count": 6,
   "id": "928f4582",
   "metadata": {},
   "outputs": [
    {
     "data": {
      "text/html": [
       "<div>\n",
       "<style scoped>\n",
       "    .dataframe tbody tr th:only-of-type {\n",
       "        vertical-align: middle;\n",
       "    }\n",
       "\n",
       "    .dataframe tbody tr th {\n",
       "        vertical-align: top;\n",
       "    }\n",
       "\n",
       "    .dataframe thead th {\n",
       "        text-align: right;\n",
       "    }\n",
       "</style>\n",
       "<table border=\"1\" class=\"dataframe\">\n",
       "  <thead>\n",
       "    <tr style=\"text-align: right;\">\n",
       "      <th></th>\n",
       "      <th>Taxonomy</th>\n",
       "      <th>Virus</th>\n",
       "      <th>Accession_number</th>\n",
       "      <th>Class_label</th>\n",
       "      <th>FASTA</th>\n",
       "    </tr>\n",
       "  </thead>\n",
       "  <tbody>\n",
       "    <tr>\n",
       "      <th>0</th>\n",
       "      <td>Adnaviria</td>\n",
       "      <td>Acidianus filamentous virus 1</td>\n",
       "      <td>NC_005830</td>\n",
       "      <td>1</td>\n",
       "      <td>CGGGGGGGAGCATGTGGTTTGCGGTTTGAGGTTCGCACTTGTGATT...</td>\n",
       "    </tr>\n",
       "    <tr>\n",
       "      <th>1</th>\n",
       "      <td>Adnaviria</td>\n",
       "      <td>Acidianus filamentous virus 2</td>\n",
       "      <td>NC_009884</td>\n",
       "      <td>1</td>\n",
       "      <td>GTATATATACGGTAAAATACCCAGACGATATTCTCCGTCAGTTTGA...</td>\n",
       "    </tr>\n",
       "    <tr>\n",
       "      <th>2</th>\n",
       "      <td>Adnaviria</td>\n",
       "      <td>Acidianus filamentous virus 3</td>\n",
       "      <td>NC_010155</td>\n",
       "      <td>1</td>\n",
       "      <td>TAACATCAAGTATGAGGATACTACACACAACATAAAGTATCTACAC...</td>\n",
       "    </tr>\n",
       "    <tr>\n",
       "      <th>3</th>\n",
       "      <td>Adnaviria</td>\n",
       "      <td>Acidianus filamentous virus 6</td>\n",
       "      <td>NC_010152</td>\n",
       "      <td>1</td>\n",
       "      <td>AGCTTTTTTCTCTAGATAGAGAATGTAGTATCAAGTATCAAGATAC...</td>\n",
       "    </tr>\n",
       "    <tr>\n",
       "      <th>4</th>\n",
       "      <td>Adnaviria</td>\n",
       "      <td>Acidianus filamentous virus 7</td>\n",
       "      <td>NC_010153</td>\n",
       "      <td>1</td>\n",
       "      <td>TAAGTCATTTCCCCCTTTTATATATAAAGATACATATCACACACCC...</td>\n",
       "    </tr>\n",
       "    <tr>\n",
       "      <th>...</th>\n",
       "      <td>...</td>\n",
       "      <td>...</td>\n",
       "      <td>...</td>\n",
       "      <td>...</td>\n",
       "      <td>...</td>\n",
       "    </tr>\n",
       "    <tr>\n",
       "      <th>191</th>\n",
       "      <td>Riboviria</td>\n",
       "      <td>Woodlouse hunter spider associated circular vi...</td>\n",
       "      <td>NC_040343</td>\n",
       "      <td>31</td>\n",
       "      <td>TAATAGTAGCCCTGACCCCCTTCTGTGCAAGTTTAATTCATTAGAA...</td>\n",
       "    </tr>\n",
       "    <tr>\n",
       "      <th>192</th>\n",
       "      <td>Riboviria</td>\n",
       "      <td>Yerba mate-associated circular DNA virus 1</td>\n",
       "      <td>NC_040708</td>\n",
       "      <td>31</td>\n",
       "      <td>ACCCCCAACCTCCCGTCCCGTCCAATTTATGCCCACGTGGAATAGC...</td>\n",
       "    </tr>\n",
       "    <tr>\n",
       "      <th>193</th>\n",
       "      <td>Riboviria</td>\n",
       "      <td>Zirqa virus</td>\n",
       "      <td>NC_040521</td>\n",
       "      <td>31</td>\n",
       "      <td>CYGTGTGTACACGTATATAGATATCTACTTCTGATTAGGTGGCTTT...</td>\n",
       "    </tr>\n",
       "    <tr>\n",
       "      <th>194</th>\n",
       "      <td>Riboviria</td>\n",
       "      <td>Zirqa virus</td>\n",
       "      <td>NC_040520</td>\n",
       "      <td>31</td>\n",
       "      <td>ACATCATTTGATAGAAAGTCTTGCAGCAATCCCCCTTTGAGTACTT...</td>\n",
       "    </tr>\n",
       "    <tr>\n",
       "      <th>195</th>\n",
       "      <td>Riboviria</td>\n",
       "      <td>Zirqa virus</td>\n",
       "      <td>NC_040519</td>\n",
       "      <td>31</td>\n",
       "      <td>TCTCAAAGATANAAATCCTCTAACCCCCCCATAAGTTACCTAAACA...</td>\n",
       "    </tr>\n",
       "  </tbody>\n",
       "</table>\n",
       "<p>14438 rows × 5 columns</p>\n",
       "</div>"
      ],
      "text/plain": [
       "      Taxonomy                                              Virus  \\\n",
       "0    Adnaviria                      Acidianus filamentous virus 1   \n",
       "1    Adnaviria                      Acidianus filamentous virus 2   \n",
       "2    Adnaviria                      Acidianus filamentous virus 3   \n",
       "3    Adnaviria                      Acidianus filamentous virus 6   \n",
       "4    Adnaviria                      Acidianus filamentous virus 7   \n",
       "..         ...                                                ...   \n",
       "191  Riboviria  Woodlouse hunter spider associated circular vi...   \n",
       "192  Riboviria         Yerba mate-associated circular DNA virus 1   \n",
       "193  Riboviria                                        Zirqa virus   \n",
       "194  Riboviria                                        Zirqa virus   \n",
       "195  Riboviria                                        Zirqa virus   \n",
       "\n",
       "    Accession_number  Class_label  \\\n",
       "0          NC_005830            1   \n",
       "1          NC_009884            1   \n",
       "2          NC_010155            1   \n",
       "3          NC_010152            1   \n",
       "4          NC_010153            1   \n",
       "..               ...          ...   \n",
       "191        NC_040343           31   \n",
       "192        NC_040708           31   \n",
       "193        NC_040521           31   \n",
       "194        NC_040520           31   \n",
       "195        NC_040519           31   \n",
       "\n",
       "                                                 FASTA  \n",
       "0    CGGGGGGGAGCATGTGGTTTGCGGTTTGAGGTTCGCACTTGTGATT...  \n",
       "1    GTATATATACGGTAAAATACCCAGACGATATTCTCCGTCAGTTTGA...  \n",
       "2    TAACATCAAGTATGAGGATACTACACACAACATAAAGTATCTACAC...  \n",
       "3    AGCTTTTTTCTCTAGATAGAGAATGTAGTATCAAGTATCAAGATAC...  \n",
       "4    TAAGTCATTTCCCCCTTTTATATATAAAGATACATATCACACACCC...  \n",
       "..                                                 ...  \n",
       "191  TAATAGTAGCCCTGACCCCCTTCTGTGCAAGTTTAATTCATTAGAA...  \n",
       "192  ACCCCCAACCTCCCGTCCCGTCCAATTTATGCCCACGTGGAATAGC...  \n",
       "193  CYGTGTGTACACGTATATAGATATCTACTTCTGATTAGGTGGCTTT...  \n",
       "194  ACATCATTTGATAGAAAGTCTTGCAGCAATCCCCCTTTGAGTACTT...  \n",
       "195  TCTCAAAGATANAAATCCTCTAACCCCCCCATAAGTTACCTAAACA...  \n",
       "\n",
       "[14438 rows x 5 columns]"
      ]
     },
     "execution_count": 6,
     "metadata": {},
     "output_type": "execute_result"
    }
   ],
   "source": [
    "combined_csv_data = pd.concat([pd.read_csv(f) for f in all_filenames])\n",
    "combined_csv_data.drop_duplicates()"
   ]
  },
  {
   "cell_type": "code",
   "execution_count": 19,
   "id": "e7fc4b13",
   "metadata": {},
   "outputs": [],
   "source": [
    "combined_csv_data.to_csv(\"../Virus_classification_data.csv\", index= False)"
   ]
  },
  {
   "cell_type": "code",
   "execution_count": null,
   "id": "e9bbcb03",
   "metadata": {},
   "outputs": [],
   "source": []
  }
 ],
 "metadata": {
  "kernelspec": {
   "display_name": "Python 3",
   "language": "python",
   "name": "python3"
  },
  "language_info": {
   "codemirror_mode": {
    "name": "ipython",
    "version": 3
   },
   "file_extension": ".py",
   "mimetype": "text/x-python",
   "name": "python",
   "nbconvert_exporter": "python",
   "pygments_lexer": "ipython3",
   "version": "3.8.8"
  }
 },
 "nbformat": 4,
 "nbformat_minor": 5
}
